# Issue 26992: Fix new (lib) gap on py3

archive/issues_026755.json:
```json
{
    "body": "There are py3-specific bugs in the new lib gap, as of #22626.\nSome of them stem from error handler not being fully string/bytes clean.\n\n```\n3$ ./sage -tp src/sage/libs/gap/util.pyx\nRunning doctests with ID 2019-01-02-09-11-48-97f4ca0c.\nGit branch: HEAD\nUsing --optional=dochtml,memlimit,mpir,python2,sage\nDoctesting 1 file using 8 threads.\nsage -t --warn-long 46.7 src/sage/libs/gap/util.pyx\n**********************************************************************\nFile \"src/sage/libs/gap/util.pyx\", line 389, in sage.libs.gap.util.NULL\nFailed example:\n    libgap.eval('Complex Field with 53 bits of precision;')\nExpected:\n    Traceback (most recent call last):\n    ...\n    ValueError: libGAP: Error, Variable: 'Complex' must have a value\n    Syntax error: ; expected in stream:1\n    Complex Field with 53 bits of precision;;\n     ^^^^^^^^^^^^\n    Error, Variable: 'with' must have a value\n    Syntax error: ; expected in stream:1\n    Complex Field with 53 bits of precision;;\n     ^^^^^^^^^^^^^^^^^^^^\n    Error, Variable: 'bits' must have a value\n    Syntax error: ; expected in stream:1\n    Complex Field with 53 bits of precision;;\n     ^^^^^^^^^^^^^^^^^^^^^^^^^^^^\n    Error, Variable: 'precision' must have a value\nGot:\n    RuntimeError: Error, Variable: 'Complex' must have a value\n    <BLANKLINE>\n    The above exception was the direct cause of the following exception:\n    <BLANKLINE>\n    Traceback (most recent call last):\n      File \"sage/libs/gap/util.pyx\", line 510, in sage.libs.gap.util.extract_libgap_errout (build/cythonized/sage/libs/gap/util.c:6662)\n    SystemError: <built-in method replace of str object at 0x7fd29cec5af8> returned a result with an error set\n    Exception ignored in: 'sage.libs.gap.util.error_handler'\n    Traceback (most recent call last):\n      File \"sage/libs/gap/util.pyx\", line 510, in sage.libs.gap.util.extract_libgap_errout (build/cythonized/sage/libs/gap/util.c:6662)\n    SystemError: <built-in method replace of str object at 0x7fd29cec5af8> returned a result with an error set\n    RuntimeError: Syntax error: ; expected in stream:1\n    Complex Field with 53 bits of precision;;\n     ^^^^^^^^^^^^^^^^^^^^\n    Error, Variable: 'bits' must have a value\n    <BLANKLINE>\n    The above exception was the direct cause of the following exception:\n    <BLANKLINE>\n    Traceback (most recent call last):\n      File \"sage/libs/gap/util.pyx\", line 510, in sage.libs.gap.util.extract_libgap_errout (build/cythonized/sage/libs/gap/util.c:6662)\n    SystemError: <built-in method replace of str object at 0x7fd29cc76030> returned a result with an error set\n    Exception ignored in: 'sage.libs.gap.util.error_handler'\n    Traceback (most recent call last):\n      File \"sage/libs/gap/util.pyx\", line 510, in sage.libs.gap.util.extract_libgap_errout (build/cythonized/sage/libs/gap/util.c:6662)\n    SystemError: <built-in method replace of str object at 0x7fd29cc76030> returned a result with an error set\n    Traceback (most recent call last):\n      File \"/home/dimpase/sagepy3/local/lib/python3.6/site-packages/sage/doctest/forker.py\", line 671, in _run\n        self.compile_and_execute(example, compiler, test.globs)\n      File \"/home/dimpase/sagepy3/local/lib/python3.6/site-packages/sage/doctest/forker.py\", line 1086, in compile_and_execute\n        exec(compiled, globs)\n      File \"<doctest sage.libs.gap.util.NULL[4]>\", line 1, in <module>\n        libgap.eval('Complex Field with 53 bits of precision;')\n      File \"sage/libs/gap/libgap.pyx\", line 410, in sage.libs.gap.libgap.Gap.eval (build/cythonized/sage/libs/gap/libgap.c:4360)\n        elem = make_any_gap_element(self, gap_eval(gap_command))\n      File \"sage/libs/gap/util.pyx\", line 442, in sage.libs.gap.util.gap_eval (build/cythonized/sage/libs/gap/util.c:6328)\n        raise ValueError('can only evaluate a single statement')\n    ValueError: can only evaluate a single statement\n**********************************************************************\nFile \"src/sage/libs/gap/util.pyx\", line 410, in sage.libs.gap.util.NULL\nFailed example:\n    libgap.eval('Complex Field with 53 bits of precision;')\nExpected:\n    Traceback (most recent call last):\n    ...\n    ValueError: libGAP: Error, Variable: 'Complex' must have a value\n    ...\n    Error, Variable: 'precision' must have a value\nGot:\n    RuntimeError: Error, Variable: 'Complex' must have a value\n    <BLANKLINE>\n    The above exception was the direct cause of the following exception:\n    <BLANKLINE>\n    Traceback (most recent call last):\n      File \"sage/libs/gap/util.pyx\", line 510, in sage.libs.gap.util.extract_libgap_errout (build/cythonized/sage/libs/gap/util.c:6662)\n    SystemError: <built-in method replace of str object at 0x7fd29cec5bb0> returned a result with an error set\n    Exception ignored in: 'sage.libs.gap.util.error_handler'\n    Traceback (most recent call last):\n      File \"sage/libs/gap/util.pyx\", line 510, in sage.libs.gap.util.extract_libgap_errout (build/cythonized/sage/libs/gap/util.c:6662)\n    SystemError: <built-in method replace of str object at 0x7fd29cec5bb0> returned a result with an error set\n    RuntimeError: Syntax error: ; expected in stream:1\n    Complex Field with 53 bits of precision;;\n     ^^^^^^^^^^^^^^^^^^^^\n    Error, Variable: 'bits' must have a value\n    <BLANKLINE>\n    The above exception was the direct cause of the following exception:\n    <BLANKLINE>\n    Traceback (most recent call last):\n      File \"sage/libs/gap/util.pyx\", line 510, in sage.libs.gap.util.extract_libgap_errout (build/cythonized/sage/libs/gap/util.c:6662)\n    SystemError: <built-in method replace of str object at 0x7fd29cc77030> returned a result with an error set\n    Exception ignored in: 'sage.libs.gap.util.error_handler'\n    Traceback (most recent call last):\n      File \"sage/libs/gap/util.pyx\", line 510, in sage.libs.gap.util.extract_libgap_errout (build/cythonized/sage/libs/gap/util.c:6662)\n    SystemError: <built-in method replace of str object at 0x7fd29cc77030> returned a result with an error set\n    Traceback (most recent call last):\n      File \"/home/dimpase/sagepy3/local/lib/python3.6/site-packages/sage/doctest/forker.py\", line 671, in _run\n        self.compile_and_execute(example, compiler, test.globs)\n      File \"/home/dimpase/sagepy3/local/lib/python3.6/site-packages/sage/doctest/forker.py\", line 1086, in compile_and_execute\n        exec(compiled, globs)\n      File \"<doctest sage.libs.gap.util.NULL[5]>\", line 1, in <module>\n        libgap.eval('Complex Field with 53 bits of precision;')\n      File \"sage/libs/gap/libgap.pyx\", line 410, in sage.libs.gap.libgap.Gap.eval (build/cythonized/sage/libs/gap/libgap.c:4360)\n        elem = make_any_gap_element(self, gap_eval(gap_command))\n      File \"sage/libs/gap/util.pyx\", line 442, in sage.libs.gap.util.gap_eval (build/cythonized/sage/libs/gap/util.c:6328)\n        raise ValueError('can only evaluate a single statement')\n    ValueError: can only evaluate a single statement\n**********************************************************************\n1 item had failures:\n   2 of   8 in sage.libs.gap.util.NULL\n    [21 tests, 2 failures, 1.75 s]\n----------------------------------------------------------------------\nsage -t --warn-long 46.7 src/sage/libs/gap/util.pyx  # 2 doctests failed\n----------------------------------------------------------------------\nTotal time for all tests: 1.8 seconds\n    cpu time: 1.8 seconds\n    cumulative wall time: 1.8 seconds\n```\n\nAssignee: @embray\n\nCC:  @fchapoton @embray @jdemeyer\n\nBranch/Commit: 369fade0a5c2ce0f5a6452d5e07065fd038bf07f\n\nReviewer: Dima Pasechnik\n\nAuthor: Erik Bray\n\nResolution: fixed\n\nIssue created by migration from https://trac.sagemath.org/ticket/26992\n\n",
    "closed_at": "2019-02-06T10:39:19Z",
    "created_at": "2019-01-02T03:54:14Z",
    "labels": [
        "component: python3",
        "bug"
    ],
    "milestone": "https://github.com/sagemath/sagetest/milestones/sage-8.7",
    "title": "Fix new (lib) gap on py3",
    "type": "issue",
    "url": "https://github.com/sagemath/sagetest/issues/26992",
    "user": "https://github.com/dimpase"
}
```
There are py3-specific bugs in the new lib gap, as of #22626.
Some of them stem from error handler not being fully string/bytes clean.

```
3$ ./sage -tp src/sage/libs/gap/util.pyx
Running doctests with ID 2019-01-02-09-11-48-97f4ca0c.
Git branch: HEAD
Using --optional=dochtml,memlimit,mpir,python2,sage
Doctesting 1 file using 8 threads.
sage -t --warn-long 46.7 src/sage/libs/gap/util.pyx
**********************************************************************
File "src/sage/libs/gap/util.pyx", line 389, in sage.libs.gap.util.NULL
Failed example:
    libgap.eval('Complex Field with 53 bits of precision;')
Expected:
    Traceback (most recent call last):
    ...
    ValueError: libGAP: Error, Variable: 'Complex' must have a value
    Syntax error: ; expected in stream:1
    Complex Field with 53 bits of precision;;
     ^^^^^^^^^^^^
    Error, Variable: 'with' must have a value
    Syntax error: ; expected in stream:1
    Complex Field with 53 bits of precision;;
     ^^^^^^^^^^^^^^^^^^^^
    Error, Variable: 'bits' must have a value
    Syntax error: ; expected in stream:1
    Complex Field with 53 bits of precision;;
     ^^^^^^^^^^^^^^^^^^^^^^^^^^^^
    Error, Variable: 'precision' must have a value
Got:
    RuntimeError: Error, Variable: 'Complex' must have a value
    <BLANKLINE>
    The above exception was the direct cause of the following exception:
    <BLANKLINE>
    Traceback (most recent call last):
      File "sage/libs/gap/util.pyx", line 510, in sage.libs.gap.util.extract_libgap_errout (build/cythonized/sage/libs/gap/util.c:6662)
    SystemError: <built-in method replace of str object at 0x7fd29cec5af8> returned a result with an error set
    Exception ignored in: 'sage.libs.gap.util.error_handler'
    Traceback (most recent call last):
      File "sage/libs/gap/util.pyx", line 510, in sage.libs.gap.util.extract_libgap_errout (build/cythonized/sage/libs/gap/util.c:6662)
    SystemError: <built-in method replace of str object at 0x7fd29cec5af8> returned a result with an error set
    RuntimeError: Syntax error: ; expected in stream:1
    Complex Field with 53 bits of precision;;
     ^^^^^^^^^^^^^^^^^^^^
    Error, Variable: 'bits' must have a value
    <BLANKLINE>
    The above exception was the direct cause of the following exception:
    <BLANKLINE>
    Traceback (most recent call last):
      File "sage/libs/gap/util.pyx", line 510, in sage.libs.gap.util.extract_libgap_errout (build/cythonized/sage/libs/gap/util.c:6662)
    SystemError: <built-in method replace of str object at 0x7fd29cc76030> returned a result with an error set
    Exception ignored in: 'sage.libs.gap.util.error_handler'
    Traceback (most recent call last):
      File "sage/libs/gap/util.pyx", line 510, in sage.libs.gap.util.extract_libgap_errout (build/cythonized/sage/libs/gap/util.c:6662)
    SystemError: <built-in method replace of str object at 0x7fd29cc76030> returned a result with an error set
    Traceback (most recent call last):
      File "/home/dimpase/sagepy3/local/lib/python3.6/site-packages/sage/doctest/forker.py", line 671, in _run
        self.compile_and_execute(example, compiler, test.globs)
      File "/home/dimpase/sagepy3/local/lib/python3.6/site-packages/sage/doctest/forker.py", line 1086, in compile_and_execute
        exec(compiled, globs)
      File "<doctest sage.libs.gap.util.NULL[4]>", line 1, in <module>
        libgap.eval('Complex Field with 53 bits of precision;')
      File "sage/libs/gap/libgap.pyx", line 410, in sage.libs.gap.libgap.Gap.eval (build/cythonized/sage/libs/gap/libgap.c:4360)
        elem = make_any_gap_element(self, gap_eval(gap_command))
      File "sage/libs/gap/util.pyx", line 442, in sage.libs.gap.util.gap_eval (build/cythonized/sage/libs/gap/util.c:6328)
        raise ValueError('can only evaluate a single statement')
    ValueError: can only evaluate a single statement
**********************************************************************
File "src/sage/libs/gap/util.pyx", line 410, in sage.libs.gap.util.NULL
Failed example:
    libgap.eval('Complex Field with 53 bits of precision;')
Expected:
    Traceback (most recent call last):
    ...
    ValueError: libGAP: Error, Variable: 'Complex' must have a value
    ...
    Error, Variable: 'precision' must have a value
Got:
    RuntimeError: Error, Variable: 'Complex' must have a value
    <BLANKLINE>
    The above exception was the direct cause of the following exception:
    <BLANKLINE>
    Traceback (most recent call last):
      File "sage/libs/gap/util.pyx", line 510, in sage.libs.gap.util.extract_libgap_errout (build/cythonized/sage/libs/gap/util.c:6662)
    SystemError: <built-in method replace of str object at 0x7fd29cec5bb0> returned a result with an error set
    Exception ignored in: 'sage.libs.gap.util.error_handler'
    Traceback (most recent call last):
      File "sage/libs/gap/util.pyx", line 510, in sage.libs.gap.util.extract_libgap_errout (build/cythonized/sage/libs/gap/util.c:6662)
    SystemError: <built-in method replace of str object at 0x7fd29cec5bb0> returned a result with an error set
    RuntimeError: Syntax error: ; expected in stream:1
    Complex Field with 53 bits of precision;;
     ^^^^^^^^^^^^^^^^^^^^
    Error, Variable: 'bits' must have a value
    <BLANKLINE>
    The above exception was the direct cause of the following exception:
    <BLANKLINE>
    Traceback (most recent call last):
      File "sage/libs/gap/util.pyx", line 510, in sage.libs.gap.util.extract_libgap_errout (build/cythonized/sage/libs/gap/util.c:6662)
    SystemError: <built-in method replace of str object at 0x7fd29cc77030> returned a result with an error set
    Exception ignored in: 'sage.libs.gap.util.error_handler'
    Traceback (most recent call last):
      File "sage/libs/gap/util.pyx", line 510, in sage.libs.gap.util.extract_libgap_errout (build/cythonized/sage/libs/gap/util.c:6662)
    SystemError: <built-in method replace of str object at 0x7fd29cc77030> returned a result with an error set
    Traceback (most recent call last):
      File "/home/dimpase/sagepy3/local/lib/python3.6/site-packages/sage/doctest/forker.py", line 671, in _run
        self.compile_and_execute(example, compiler, test.globs)
      File "/home/dimpase/sagepy3/local/lib/python3.6/site-packages/sage/doctest/forker.py", line 1086, in compile_and_execute
        exec(compiled, globs)
      File "<doctest sage.libs.gap.util.NULL[5]>", line 1, in <module>
        libgap.eval('Complex Field with 53 bits of precision;')
      File "sage/libs/gap/libgap.pyx", line 410, in sage.libs.gap.libgap.Gap.eval (build/cythonized/sage/libs/gap/libgap.c:4360)
        elem = make_any_gap_element(self, gap_eval(gap_command))
      File "sage/libs/gap/util.pyx", line 442, in sage.libs.gap.util.gap_eval (build/cythonized/sage/libs/gap/util.c:6328)
        raise ValueError('can only evaluate a single statement')
    ValueError: can only evaluate a single statement
**********************************************************************
1 item had failures:
   2 of   8 in sage.libs.gap.util.NULL
    [21 tests, 2 failures, 1.75 s]
----------------------------------------------------------------------
sage -t --warn-long 46.7 src/sage/libs/gap/util.pyx  # 2 doctests failed
----------------------------------------------------------------------
Total time for all tests: 1.8 seconds
    cpu time: 1.8 seconds
    cumulative wall time: 1.8 seconds
```

Assignee: @embray

CC:  @fchapoton @embray @jdemeyer

Branch/Commit: 369fade0a5c2ce0f5a6452d5e07065fd038bf07f

Reviewer: Dima Pasechnik

Author: Erik Bray

Resolution: fixed

Issue created by migration from https://trac.sagemath.org/ticket/26992





---

archive/issue_comments_512391.json:
```json
{
    "body": "Description changed:\n``````diff\n--- \n+++ \n@@ -1,2 +1,127 @@\n There are py3-specific bugs in the new lib gap, as of #22626.\n Some of them stem from error handler not being fully string/bytes clean.\n+\n+```\n+3$ ./sage -tp src/sage/libs/gap/util.pyx\n+Running doctests with ID 2019-01-02-09-11-48-97f4ca0c.\n+Git branch: HEAD\n+Using --optional=dochtml,memlimit,mpir,python2,sage\n+Doctesting 1 file using 8 threads.\n+sage -t --warn-long 46.7 src/sage/libs/gap/util.pyx\n+**********************************************************************\n+File \"src/sage/libs/gap/util.pyx\", line 389, in sage.libs.gap.util.NULL\n+Failed example:\n+    libgap.eval('Complex Field with 53 bits of precision;')\n+Expected:\n+    Traceback (most recent call last):\n+    ...\n+    ValueError: libGAP: Error, Variable: 'Complex' must have a value\n+    Syntax error: ; expected in stream:1\n+    Complex Field with 53 bits of precision;;\n+     ^^^^^^^^^^^^\n+    Error, Variable: 'with' must have a value\n+    Syntax error: ; expected in stream:1\n+    Complex Field with 53 bits of precision;;\n+     ^^^^^^^^^^^^^^^^^^^^\n+    Error, Variable: 'bits' must have a value\n+    Syntax error: ; expected in stream:1\n+    Complex Field with 53 bits of precision;;\n+     ^^^^^^^^^^^^^^^^^^^^^^^^^^^^\n+    Error, Variable: 'precision' must have a value\n+Got:\n+    RuntimeError: Error, Variable: 'Complex' must have a value\n+    <BLANKLINE>\n+    The above exception was the direct cause of the following exception:\n+    <BLANKLINE>\n+    Traceback (most recent call last):\n+      File \"sage/libs/gap/util.pyx\", line 510, in sage.libs.gap.util.extract_libgap_errout (build/cythonized/sage/libs/gap/util.c:6662)\n+    SystemError: <built-in method replace of str object at 0x7fd29cec5af8> returned a result with an error set\n+    Exception ignored in: 'sage.libs.gap.util.error_handler'\n+    Traceback (most recent call last):\n+      File \"sage/libs/gap/util.pyx\", line 510, in sage.libs.gap.util.extract_libgap_errout (build/cythonized/sage/libs/gap/util.c:6662)\n+    SystemError: <built-in method replace of str object at 0x7fd29cec5af8> returned a result with an error set\n+    RuntimeError: Syntax error: ; expected in stream:1\n+    Complex Field with 53 bits of precision;;\n+     ^^^^^^^^^^^^^^^^^^^^\n+    Error, Variable: 'bits' must have a value\n+    <BLANKLINE>\n+    The above exception was the direct cause of the following exception:\n+    <BLANKLINE>\n+    Traceback (most recent call last):\n+      File \"sage/libs/gap/util.pyx\", line 510, in sage.libs.gap.util.extract_libgap_errout (build/cythonized/sage/libs/gap/util.c:6662)\n+    SystemError: <built-in method replace of str object at 0x7fd29cc76030> returned a result with an error set\n+    Exception ignored in: 'sage.libs.gap.util.error_handler'\n+    Traceback (most recent call last):\n+      File \"sage/libs/gap/util.pyx\", line 510, in sage.libs.gap.util.extract_libgap_errout (build/cythonized/sage/libs/gap/util.c:6662)\n+    SystemError: <built-in method replace of str object at 0x7fd29cc76030> returned a result with an error set\n+    Traceback (most recent call last):\n+      File \"/home/dimpase/sagepy3/local/lib/python3.6/site-packages/sage/doctest/forker.py\", line 671, in _run\n+        self.compile_and_execute(example, compiler, test.globs)\n+      File \"/home/dimpase/sagepy3/local/lib/python3.6/site-packages/sage/doctest/forker.py\", line 1086, in compile_and_execute\n+        exec(compiled, globs)\n+      File \"<doctest sage.libs.gap.util.NULL[4]>\", line 1, in <module>\n+        libgap.eval('Complex Field with 53 bits of precision;')\n+      File \"sage/libs/gap/libgap.pyx\", line 410, in sage.libs.gap.libgap.Gap.eval (build/cythonized/sage/libs/gap/libgap.c:4360)\n+        elem = make_any_gap_element(self, gap_eval(gap_command))\n+      File \"sage/libs/gap/util.pyx\", line 442, in sage.libs.gap.util.gap_eval (build/cythonized/sage/libs/gap/util.c:6328)\n+        raise ValueError('can only evaluate a single statement')\n+    ValueError: can only evaluate a single statement\n+**********************************************************************\n+File \"src/sage/libs/gap/util.pyx\", line 410, in sage.libs.gap.util.NULL\n+Failed example:\n+    libgap.eval('Complex Field with 53 bits of precision;')\n+Expected:\n+    Traceback (most recent call last):\n+    ...\n+    ValueError: libGAP: Error, Variable: 'Complex' must have a value\n+    ...\n+    Error, Variable: 'precision' must have a value\n+Got:\n+    RuntimeError: Error, Variable: 'Complex' must have a value\n+    <BLANKLINE>\n+    The above exception was the direct cause of the following exception:\n+    <BLANKLINE>\n+    Traceback (most recent call last):\n+      File \"sage/libs/gap/util.pyx\", line 510, in sage.libs.gap.util.extract_libgap_errout (build/cythonized/sage/libs/gap/util.c:6662)\n+    SystemError: <built-in method replace of str object at 0x7fd29cec5bb0> returned a result with an error set\n+    Exception ignored in: 'sage.libs.gap.util.error_handler'\n+    Traceback (most recent call last):\n+      File \"sage/libs/gap/util.pyx\", line 510, in sage.libs.gap.util.extract_libgap_errout (build/cythonized/sage/libs/gap/util.c:6662)\n+    SystemError: <built-in method replace of str object at 0x7fd29cec5bb0> returned a result with an error set\n+    RuntimeError: Syntax error: ; expected in stream:1\n+    Complex Field with 53 bits of precision;;\n+     ^^^^^^^^^^^^^^^^^^^^\n+    Error, Variable: 'bits' must have a value\n+    <BLANKLINE>\n+    The above exception was the direct cause of the following exception:\n+    <BLANKLINE>\n+    Traceback (most recent call last):\n+      File \"sage/libs/gap/util.pyx\", line 510, in sage.libs.gap.util.extract_libgap_errout (build/cythonized/sage/libs/gap/util.c:6662)\n+    SystemError: <built-in method replace of str object at 0x7fd29cc77030> returned a result with an error set\n+    Exception ignored in: 'sage.libs.gap.util.error_handler'\n+    Traceback (most recent call last):\n+      File \"sage/libs/gap/util.pyx\", line 510, in sage.libs.gap.util.extract_libgap_errout (build/cythonized/sage/libs/gap/util.c:6662)\n+    SystemError: <built-in method replace of str object at 0x7fd29cc77030> returned a result with an error set\n+    Traceback (most recent call last):\n+      File \"/home/dimpase/sagepy3/local/lib/python3.6/site-packages/sage/doctest/forker.py\", line 671, in _run\n+        self.compile_and_execute(example, compiler, test.globs)\n+      File \"/home/dimpase/sagepy3/local/lib/python3.6/site-packages/sage/doctest/forker.py\", line 1086, in compile_and_execute\n+        exec(compiled, globs)\n+      File \"<doctest sage.libs.gap.util.NULL[5]>\", line 1, in <module>\n+        libgap.eval('Complex Field with 53 bits of precision;')\n+      File \"sage/libs/gap/libgap.pyx\", line 410, in sage.libs.gap.libgap.Gap.eval (build/cythonized/sage/libs/gap/libgap.c:4360)\n+        elem = make_any_gap_element(self, gap_eval(gap_command))\n+      File \"sage/libs/gap/util.pyx\", line 442, in sage.libs.gap.util.gap_eval (build/cythonized/sage/libs/gap/util.c:6328)\n+        raise ValueError('can only evaluate a single statement')\n+    ValueError: can only evaluate a single statement\n+**********************************************************************\n+1 item had failures:\n+   2 of   8 in sage.libs.gap.util.NULL\n+    [21 tests, 2 failures, 1.75 s]\n+----------------------------------------------------------------------\n+sage -t --warn-long 46.7 src/sage/libs/gap/util.pyx  # 2 doctests failed\n+----------------------------------------------------------------------\n+Total time for all tests: 1.8 seconds\n+    cpu time: 1.8 seconds\n+    cumulative wall time: 1.8 seconds\n+```\n``````\n",
    "created_at": "2019-01-02T09:15:21Z",
    "issue": "https://github.com/sagemath/sagetest/issues/26992",
    "type": "issue_comment",
    "url": "https://github.com/sagemath/sagetest/issues/26992#issuecomment-512391",
    "user": "https://github.com/dimpase"
}
```

Description changed:
``````diff
--- 
+++ 
@@ -1,2 +1,127 @@
 There are py3-specific bugs in the new lib gap, as of #22626.
 Some of them stem from error handler not being fully string/bytes clean.
+
+```
+3$ ./sage -tp src/sage/libs/gap/util.pyx
+Running doctests with ID 2019-01-02-09-11-48-97f4ca0c.
+Git branch: HEAD
+Using --optional=dochtml,memlimit,mpir,python2,sage
+Doctesting 1 file using 8 threads.
+sage -t --warn-long 46.7 src/sage/libs/gap/util.pyx
+**********************************************************************
+File "src/sage/libs/gap/util.pyx", line 389, in sage.libs.gap.util.NULL
+Failed example:
+    libgap.eval('Complex Field with 53 bits of precision;')
+Expected:
+    Traceback (most recent call last):
+    ...
+    ValueError: libGAP: Error, Variable: 'Complex' must have a value
+    Syntax error: ; expected in stream:1
+    Complex Field with 53 bits of precision;;
+     ^^^^^^^^^^^^
+    Error, Variable: 'with' must have a value
+    Syntax error: ; expected in stream:1
+    Complex Field with 53 bits of precision;;
+     ^^^^^^^^^^^^^^^^^^^^
+    Error, Variable: 'bits' must have a value
+    Syntax error: ; expected in stream:1
+    Complex Field with 53 bits of precision;;
+     ^^^^^^^^^^^^^^^^^^^^^^^^^^^^
+    Error, Variable: 'precision' must have a value
+Got:
+    RuntimeError: Error, Variable: 'Complex' must have a value
+    <BLANKLINE>
+    The above exception was the direct cause of the following exception:
+    <BLANKLINE>
+    Traceback (most recent call last):
+      File "sage/libs/gap/util.pyx", line 510, in sage.libs.gap.util.extract_libgap_errout (build/cythonized/sage/libs/gap/util.c:6662)
+    SystemError: <built-in method replace of str object at 0x7fd29cec5af8> returned a result with an error set
+    Exception ignored in: 'sage.libs.gap.util.error_handler'
+    Traceback (most recent call last):
+      File "sage/libs/gap/util.pyx", line 510, in sage.libs.gap.util.extract_libgap_errout (build/cythonized/sage/libs/gap/util.c:6662)
+    SystemError: <built-in method replace of str object at 0x7fd29cec5af8> returned a result with an error set
+    RuntimeError: Syntax error: ; expected in stream:1
+    Complex Field with 53 bits of precision;;
+     ^^^^^^^^^^^^^^^^^^^^
+    Error, Variable: 'bits' must have a value
+    <BLANKLINE>
+    The above exception was the direct cause of the following exception:
+    <BLANKLINE>
+    Traceback (most recent call last):
+      File "sage/libs/gap/util.pyx", line 510, in sage.libs.gap.util.extract_libgap_errout (build/cythonized/sage/libs/gap/util.c:6662)
+    SystemError: <built-in method replace of str object at 0x7fd29cc76030> returned a result with an error set
+    Exception ignored in: 'sage.libs.gap.util.error_handler'
+    Traceback (most recent call last):
+      File "sage/libs/gap/util.pyx", line 510, in sage.libs.gap.util.extract_libgap_errout (build/cythonized/sage/libs/gap/util.c:6662)
+    SystemError: <built-in method replace of str object at 0x7fd29cc76030> returned a result with an error set
+    Traceback (most recent call last):
+      File "/home/dimpase/sagepy3/local/lib/python3.6/site-packages/sage/doctest/forker.py", line 671, in _run
+        self.compile_and_execute(example, compiler, test.globs)
+      File "/home/dimpase/sagepy3/local/lib/python3.6/site-packages/sage/doctest/forker.py", line 1086, in compile_and_execute
+        exec(compiled, globs)
+      File "<doctest sage.libs.gap.util.NULL[4]>", line 1, in <module>
+        libgap.eval('Complex Field with 53 bits of precision;')
+      File "sage/libs/gap/libgap.pyx", line 410, in sage.libs.gap.libgap.Gap.eval (build/cythonized/sage/libs/gap/libgap.c:4360)
+        elem = make_any_gap_element(self, gap_eval(gap_command))
+      File "sage/libs/gap/util.pyx", line 442, in sage.libs.gap.util.gap_eval (build/cythonized/sage/libs/gap/util.c:6328)
+        raise ValueError('can only evaluate a single statement')
+    ValueError: can only evaluate a single statement
+**********************************************************************
+File "src/sage/libs/gap/util.pyx", line 410, in sage.libs.gap.util.NULL
+Failed example:
+    libgap.eval('Complex Field with 53 bits of precision;')
+Expected:
+    Traceback (most recent call last):
+    ...
+    ValueError: libGAP: Error, Variable: 'Complex' must have a value
+    ...
+    Error, Variable: 'precision' must have a value
+Got:
+    RuntimeError: Error, Variable: 'Complex' must have a value
+    <BLANKLINE>
+    The above exception was the direct cause of the following exception:
+    <BLANKLINE>
+    Traceback (most recent call last):
+      File "sage/libs/gap/util.pyx", line 510, in sage.libs.gap.util.extract_libgap_errout (build/cythonized/sage/libs/gap/util.c:6662)
+    SystemError: <built-in method replace of str object at 0x7fd29cec5bb0> returned a result with an error set
+    Exception ignored in: 'sage.libs.gap.util.error_handler'
+    Traceback (most recent call last):
+      File "sage/libs/gap/util.pyx", line 510, in sage.libs.gap.util.extract_libgap_errout (build/cythonized/sage/libs/gap/util.c:6662)
+    SystemError: <built-in method replace of str object at 0x7fd29cec5bb0> returned a result with an error set
+    RuntimeError: Syntax error: ; expected in stream:1
+    Complex Field with 53 bits of precision;;
+     ^^^^^^^^^^^^^^^^^^^^
+    Error, Variable: 'bits' must have a value
+    <BLANKLINE>
+    The above exception was the direct cause of the following exception:
+    <BLANKLINE>
+    Traceback (most recent call last):
+      File "sage/libs/gap/util.pyx", line 510, in sage.libs.gap.util.extract_libgap_errout (build/cythonized/sage/libs/gap/util.c:6662)
+    SystemError: <built-in method replace of str object at 0x7fd29cc77030> returned a result with an error set
+    Exception ignored in: 'sage.libs.gap.util.error_handler'
+    Traceback (most recent call last):
+      File "sage/libs/gap/util.pyx", line 510, in sage.libs.gap.util.extract_libgap_errout (build/cythonized/sage/libs/gap/util.c:6662)
+    SystemError: <built-in method replace of str object at 0x7fd29cc77030> returned a result with an error set
+    Traceback (most recent call last):
+      File "/home/dimpase/sagepy3/local/lib/python3.6/site-packages/sage/doctest/forker.py", line 671, in _run
+        self.compile_and_execute(example, compiler, test.globs)
+      File "/home/dimpase/sagepy3/local/lib/python3.6/site-packages/sage/doctest/forker.py", line 1086, in compile_and_execute
+        exec(compiled, globs)
+      File "<doctest sage.libs.gap.util.NULL[5]>", line 1, in <module>
+        libgap.eval('Complex Field with 53 bits of precision;')
+      File "sage/libs/gap/libgap.pyx", line 410, in sage.libs.gap.libgap.Gap.eval (build/cythonized/sage/libs/gap/libgap.c:4360)
+        elem = make_any_gap_element(self, gap_eval(gap_command))
+      File "sage/libs/gap/util.pyx", line 442, in sage.libs.gap.util.gap_eval (build/cythonized/sage/libs/gap/util.c:6328)
+        raise ValueError('can only evaluate a single statement')
+    ValueError: can only evaluate a single statement
+**********************************************************************
+1 item had failures:
+   2 of   8 in sage.libs.gap.util.NULL
+    [21 tests, 2 failures, 1.75 s]
+----------------------------------------------------------------------
+sage -t --warn-long 46.7 src/sage/libs/gap/util.pyx  # 2 doctests failed
+----------------------------------------------------------------------
+Total time for all tests: 1.8 seconds
+    cpu time: 1.8 seconds
+    cumulative wall time: 1.8 seconds
+```
``````




---

archive/issue_comments_512392.json:
```json
{
    "body": "<a id='comment:2'></a>\nreducing the number of words in that string:\n\n```\nsage:  libgap.eval('Complex Field with;')\n---------------------------------------------------------------------------\nRuntimeError                              Traceback (most recent call last)\nRuntimeError: Error, Variable: 'Complex' must have a value\n\nThe above exception was the direct cause of the following exception:\n\nSystemError                               Traceback (most recent call last)\n/home/dimpase/sagepy3/local/lib/python3.6/site-packages/sage/libs/gap/util.pyx in sage.libs.gap.util.extract_libgap_errout (build/cythonized/sage/libs/gap/util.c:6662)()\n    508     if msg != NULL:\n    509         msg_py = char_to_str(msg)\n--> 510         msg_py = msg_py.replace('For debugging hints type ?Recovery from '\n    511                                 'NoMethodFound\\n', '').strip()\n    512     else:\n\nSystemError: <built-in method replace of str object at 0x7fe880330618> returned a result with an error set\nException ignored in: 'sage.libs.gap.util.error_handler'\nTraceback (most recent call last):\n  File \"sage/libs/gap/util.pyx\", line 510, in sage.libs.gap.util.extract_libgap_errout (build/cythonized/sage/libs/gap/util.c:6662)\nSystemError: <built-in method replace of str object at 0x7fe880330618> returned a result with an error set\n---------------------------------------------------------------------------\nValueError                                Traceback (most recent call last)\n<ipython-input-1-b7d3bc318a36> in <module>()\n----> 1 libgap.eval('Complex Field with;')\n\n/home/dimpase/sagepy3/local/lib/python3.6/site-packages/sage/libs/gap/libgap.pyx in sage.libs.gap.libgap.Gap.eval (build/cythonized/sage/libs/gap/libgap.c:4360)()\n    408             gap_command = str(gap_command._gap_init_())\n    409 \n--> 410         elem = make_any_gap_element(self, gap_eval(gap_command))\n    411 \n    412         # If the element is NULL just return None instead\n\n/home/dimpase/sagepy3/local/lib/python3.6/site-packages/sage/libs/gap/util.pyx in sage.libs.gap.util.gap_eval (build/cythonized/sage/libs/gap/util.c:6328)()\n    440         if nresults > 1:  # to mimick the old libGAP\n    441             # TODO: Get rid of this restriction eventually?\n--> 442             raise ValueError('can only evaluate a single statement')\n    443 \n    444         # Get the result of the first statement\n\nValueError: can only evaluate a single statement\n```\nstill the same\n\n```\nsage:  libgap.eval('Complex Field;')\n---------------------------------------------------------------------------\nRuntimeError                              Traceback (most recent call last)\n/home/dimpase/sagepy3/local/lib/python3.6/site-packages/sage/libs/gap/util.pyx in sage.libs.gap.util.gap_eval (build/cythonized/sage/libs/gap/util.c:6295)()\n    430         GAP_Enter()\n--> 431         result = GAP_EvalString(cmd)\n    432         # We can assume that the result object is a GAP PList (plain list)\n\nRuntimeError: Error, Variable: 'Complex' must have a value\n\nDuring handling of the above exception, another exception occurred:\n\nValueError                                Traceback (most recent call last)\n<ipython-input-2-124a0085564b> in <module>()\n----> 1 libgap.eval('Complex Field;')\n\n/home/dimpase/sagepy3/local/lib/python3.6/site-packages/sage/libs/gap/libgap.pyx in sage.libs.gap.libgap.Gap.eval (build/cythonized/sage/libs/gap/libgap.c:4360)()\n    408             gap_command = str(gap_command._gap_init_())\n    409 \n--> 410         elem = make_any_gap_element(self, gap_eval(gap_command))\n    411 \n    412         # If the element is NULL just return None instead\n\n/home/dimpase/sagepy3/local/lib/python3.6/site-packages/sage/libs/gap/util.pyx in sage.libs.gap.util.gap_eval (build/cythonized/sage/libs/gap/util.c:6432)()\n    459         return ELM0_LIST(result, 2)\n    460     except RuntimeError as msg:\n--> 461         raise ValueError(f'libGAP: {msg}')\n    462     finally:\n    463         GAP_Leave()\n\nValueError: libGAP: Error, Variable: 'Complex' must have a value\n```\nthis is different, more sane - this is treated as a single statement, at least.\n\n```\nsage:  libgap.eval('Complex;')\n---------------------------------------------------------------------------\nRuntimeError                              Traceback (most recent call last)\n/home/dimpase/sagepy3/local/lib/python3.6/site-packages/sage/libs/gap/util.pyx in sage.libs.gap.util.gap_eval (build/cythonized/sage/libs/gap/util.c:6295)()\n    430         GAP_Enter()\n--> 431         result = GAP_EvalString(cmd)\n    432         # We can assume that the result object is a GAP PList (plain list)\n\nRuntimeError: Error, Variable: 'Complex' must have a value\n\nDuring handling of the above exception, another exception occurred:\n\nValueError                                Traceback (most recent call last)\n<ipython-input-4-4f8aa29a844d> in <module>()\n----> 1 libgap.eval('Complex;')\n\n/home/dimpase/sagepy3/local/lib/python3.6/site-packages/sage/libs/gap/libgap.pyx in sage.libs.gap.libgap.Gap.eval (build/cythonized/sage/libs/gap/libgap.c:4360)()\n    408             gap_command = str(gap_command._gap_init_())\n    409 \n--> 410         elem = make_any_gap_element(self, gap_eval(gap_command))\n    411 \n    412         # If the element is NULL just return None instead\n\n/home/dimpase/sagepy3/local/lib/python3.6/site-packages/sage/libs/gap/util.pyx in sage.libs.gap.util.gap_eval (build/cythonized/sage/libs/gap/util.c:6432)()\n    459         return ELM0_LIST(result, 2)\n    460     except RuntimeError as msg:\n--> 461         raise ValueError(f'libGAP: {msg}')\n    462     finally:\n    463         GAP_Leave()\n\nValueError: libGAP: Error, Variable: 'Complex' must have a value\n```\nlooks OK.",
    "created_at": "2019-01-02T09:39:05Z",
    "issue": "https://github.com/sagemath/sagetest/issues/26992",
    "type": "issue_comment",
    "url": "https://github.com/sagemath/sagetest/issues/26992#issuecomment-512392",
    "user": "https://github.com/dimpase"
}
```

<a id='comment:2'></a>
reducing the number of words in that string:

```
sage:  libgap.eval('Complex Field with;')
---------------------------------------------------------------------------
RuntimeError                              Traceback (most recent call last)
RuntimeError: Error, Variable: 'Complex' must have a value

The above exception was the direct cause of the following exception:

SystemError                               Traceback (most recent call last)
/home/dimpase/sagepy3/local/lib/python3.6/site-packages/sage/libs/gap/util.pyx in sage.libs.gap.util.extract_libgap_errout (build/cythonized/sage/libs/gap/util.c:6662)()
    508     if msg != NULL:
    509         msg_py = char_to_str(msg)
--> 510         msg_py = msg_py.replace('For debugging hints type ?Recovery from '
    511                                 'NoMethodFound\n', '').strip()
    512     else:

SystemError: <built-in method replace of str object at 0x7fe880330618> returned a result with an error set
Exception ignored in: 'sage.libs.gap.util.error_handler'
Traceback (most recent call last):
  File "sage/libs/gap/util.pyx", line 510, in sage.libs.gap.util.extract_libgap_errout (build/cythonized/sage/libs/gap/util.c:6662)
SystemError: <built-in method replace of str object at 0x7fe880330618> returned a result with an error set
---------------------------------------------------------------------------
ValueError                                Traceback (most recent call last)
<ipython-input-1-b7d3bc318a36> in <module>()
----> 1 libgap.eval('Complex Field with;')

/home/dimpase/sagepy3/local/lib/python3.6/site-packages/sage/libs/gap/libgap.pyx in sage.libs.gap.libgap.Gap.eval (build/cythonized/sage/libs/gap/libgap.c:4360)()
    408             gap_command = str(gap_command._gap_init_())
    409 
--> 410         elem = make_any_gap_element(self, gap_eval(gap_command))
    411 
    412         # If the element is NULL just return None instead

/home/dimpase/sagepy3/local/lib/python3.6/site-packages/sage/libs/gap/util.pyx in sage.libs.gap.util.gap_eval (build/cythonized/sage/libs/gap/util.c:6328)()
    440         if nresults > 1:  # to mimick the old libGAP
    441             # TODO: Get rid of this restriction eventually?
--> 442             raise ValueError('can only evaluate a single statement')
    443 
    444         # Get the result of the first statement

ValueError: can only evaluate a single statement
```
still the same

```
sage:  libgap.eval('Complex Field;')
---------------------------------------------------------------------------
RuntimeError                              Traceback (most recent call last)
/home/dimpase/sagepy3/local/lib/python3.6/site-packages/sage/libs/gap/util.pyx in sage.libs.gap.util.gap_eval (build/cythonized/sage/libs/gap/util.c:6295)()
    430         GAP_Enter()
--> 431         result = GAP_EvalString(cmd)
    432         # We can assume that the result object is a GAP PList (plain list)

RuntimeError: Error, Variable: 'Complex' must have a value

During handling of the above exception, another exception occurred:

ValueError                                Traceback (most recent call last)
<ipython-input-2-124a0085564b> in <module>()
----> 1 libgap.eval('Complex Field;')

/home/dimpase/sagepy3/local/lib/python3.6/site-packages/sage/libs/gap/libgap.pyx in sage.libs.gap.libgap.Gap.eval (build/cythonized/sage/libs/gap/libgap.c:4360)()
    408             gap_command = str(gap_command._gap_init_())
    409 
--> 410         elem = make_any_gap_element(self, gap_eval(gap_command))
    411 
    412         # If the element is NULL just return None instead

/home/dimpase/sagepy3/local/lib/python3.6/site-packages/sage/libs/gap/util.pyx in sage.libs.gap.util.gap_eval (build/cythonized/sage/libs/gap/util.c:6432)()
    459         return ELM0_LIST(result, 2)
    460     except RuntimeError as msg:
--> 461         raise ValueError(f'libGAP: {msg}')
    462     finally:
    463         GAP_Leave()

ValueError: libGAP: Error, Variable: 'Complex' must have a value
```
this is different, more sane - this is treated as a single statement, at least.

```
sage:  libgap.eval('Complex;')
---------------------------------------------------------------------------
RuntimeError                              Traceback (most recent call last)
/home/dimpase/sagepy3/local/lib/python3.6/site-packages/sage/libs/gap/util.pyx in sage.libs.gap.util.gap_eval (build/cythonized/sage/libs/gap/util.c:6295)()
    430         GAP_Enter()
--> 431         result = GAP_EvalString(cmd)
    432         # We can assume that the result object is a GAP PList (plain list)

RuntimeError: Error, Variable: 'Complex' must have a value

During handling of the above exception, another exception occurred:

ValueError                                Traceback (most recent call last)
<ipython-input-4-4f8aa29a844d> in <module>()
----> 1 libgap.eval('Complex;')

/home/dimpase/sagepy3/local/lib/python3.6/site-packages/sage/libs/gap/libgap.pyx in sage.libs.gap.libgap.Gap.eval (build/cythonized/sage/libs/gap/libgap.c:4360)()
    408             gap_command = str(gap_command._gap_init_())
    409 
--> 410         elem = make_any_gap_element(self, gap_eval(gap_command))
    411 
    412         # If the element is NULL just return None instead

/home/dimpase/sagepy3/local/lib/python3.6/site-packages/sage/libs/gap/util.pyx in sage.libs.gap.util.gap_eval (build/cythonized/sage/libs/gap/util.c:6432)()
    459         return ELM0_LIST(result, 2)
    460     except RuntimeError as msg:
--> 461         raise ValueError(f'libGAP: {msg}')
    462     finally:
    463         GAP_Leave()

ValueError: libGAP: Error, Variable: 'Complex' must have a value
```
looks OK.



---

archive/issue_comments_512393.json:
```json
{
    "body": "<a id='comment:3'></a>\nAnd with python2 one gets the intended (roughly, what GAP reports):\n\n```\nsage:  libgap.eval('Complex Field with 53 bits of precision;')\n---------------------------------------------------------------------------\nValueError                                Traceback (most recent call last)\n<ipython-input-1-8255f9147a12> in <module>()\n----> 1 libgap.eval('Complex Field with 53 bits of precision;')\n\n/home/dimpase/sage/local/lib/python2.7/site-packages/sage/libs/gap/libgap.pyx in sage.libs.gap.libgap.Gap.eval (build/cythonized/sage/libs/gap/libgap.c:4360)()\n    408             gap_command = str(gap_command._gap_init_())\n    409 \n--> 410         elem = make_any_gap_element(self, gap_eval(gap_command))\n    411 \n    412         # If the element is NULL just return None instead\n\n/home/dimpase/sage/local/lib/python2.7/site-packages/sage/libs/gap/util.pyx in sage.libs.gap.util.gap_eval (build/cythonized/sage/libs/gap/util.c:6563)()\n    473         return ELM0_LIST(result, 2)\n    474     except RuntimeError as msg:\n--> 475         raise ValueError(f'libGAP: {msg}')\n    476     finally:\n    477         GAP_Leave()\n\nValueError: libGAP: Error, Variable: 'Complex' must have a value\nSyntax error: ; expected in stream:1\nComplex Field with 53 bits of precision;;\n ^^^^^^^^^^^^\nError, Variable: 'with' must have a value\nSyntax error: ; expected in stream:1\nComplex Field with 53 bits of precision;;\n ^^^^^^^^^^^^^^^^^^^^\nError, Variable: 'bits' must have a value\nSyntax error: ; expected in stream:1\nComplex Field with 53 bits of precision;;\n ^^^^^^^^^^^^^^^^^^^^^^^^^^^^\nError, Variable: 'precision' must have a value\n```",
    "created_at": "2019-01-02T09:48:23Z",
    "issue": "https://github.com/sagemath/sagetest/issues/26992",
    "type": "issue_comment",
    "url": "https://github.com/sagemath/sagetest/issues/26992#issuecomment-512393",
    "user": "https://github.com/dimpase"
}
```

<a id='comment:3'></a>
And with python2 one gets the intended (roughly, what GAP reports):

```
sage:  libgap.eval('Complex Field with 53 bits of precision;')
---------------------------------------------------------------------------
ValueError                                Traceback (most recent call last)
<ipython-input-1-8255f9147a12> in <module>()
----> 1 libgap.eval('Complex Field with 53 bits of precision;')

/home/dimpase/sage/local/lib/python2.7/site-packages/sage/libs/gap/libgap.pyx in sage.libs.gap.libgap.Gap.eval (build/cythonized/sage/libs/gap/libgap.c:4360)()
    408             gap_command = str(gap_command._gap_init_())
    409 
--> 410         elem = make_any_gap_element(self, gap_eval(gap_command))
    411 
    412         # If the element is NULL just return None instead

/home/dimpase/sage/local/lib/python2.7/site-packages/sage/libs/gap/util.pyx in sage.libs.gap.util.gap_eval (build/cythonized/sage/libs/gap/util.c:6563)()
    473         return ELM0_LIST(result, 2)
    474     except RuntimeError as msg:
--> 475         raise ValueError(f'libGAP: {msg}')
    476     finally:
    477         GAP_Leave()

ValueError: libGAP: Error, Variable: 'Complex' must have a value
Syntax error: ; expected in stream:1
Complex Field with 53 bits of precision;;
 ^^^^^^^^^^^^
Error, Variable: 'with' must have a value
Syntax error: ; expected in stream:1
Complex Field with 53 bits of precision;;
 ^^^^^^^^^^^^^^^^^^^^
Error, Variable: 'bits' must have a value
Syntax error: ; expected in stream:1
Complex Field with 53 bits of precision;;
 ^^^^^^^^^^^^^^^^^^^^^^^^^^^^
Error, Variable: 'precision' must have a value
```



---

archive/issue_comments_512394.json:
```json
{
    "body": "<a id='comment:4'></a>\nThe error comes from the new-style-formatted string in\n\n```\n--> 475    raise ValueError(f'libGAP: {msg}')\n```\nAnd indeed, this looks very dangerous coding style, as `f'` formatting allows Python expressions inside, and so a carefully constructed GAP error message may do really fun things...",
    "created_at": "2019-01-02T10:02:41Z",
    "issue": "https://github.com/sagemath/sagetest/issues/26992",
    "type": "issue_comment",
    "url": "https://github.com/sagemath/sagetest/issues/26992#issuecomment-512394",
    "user": "https://github.com/dimpase"
}
```

<a id='comment:4'></a>
The error comes from the new-style-formatted string in

```
--> 475    raise ValueError(f'libGAP: {msg}')
```
And indeed, this looks very dangerous coding style, as `f'` formatting allows Python expressions inside, and so a carefully constructed GAP error message may do really fun things...



---

archive/issue_comments_512395.json:
```json
{
    "body": "<a id='comment:5'></a>\nNo, actually, it's merely GAP producing a string that needs extra sanitation (in Python3).\nSpecifically, if I do the following\n\n```\n--- a/src/sage/libs/gap/util.pyx\n+++ b/src/sage/libs/gap/util.pyx\n@@ -507,8 +507,8 @@ cdef object extract_libgap_errout():\n     msg = CSTR_STRING(r)\n     if msg != NULL:\n         msg_py = char_to_str(msg)\n-        msg_py = msg_py.replace('For debugging hints type ?Recovery from '\n-                                'NoMethodFound\\n', '').strip()\n+        #msg_py = msg_py.replace('For debugging hints type ?Recovery from '\n+        #                        'NoMethodFound\\n', '').strip()\n     else:\n         # Shouldn't happen but just in case...\n         msg_py = \"\"\n```\nthen all the tests on this file pass.\n\nSo, somehow, Python3 cannot correctly do search/replace/strip here, while Python2 can.\nAny idea what to do?",
    "created_at": "2019-01-02T10:28:58Z",
    "issue": "https://github.com/sagemath/sagetest/issues/26992",
    "type": "issue_comment",
    "url": "https://github.com/sagemath/sagetest/issues/26992#issuecomment-512395",
    "user": "https://github.com/dimpase"
}
```

<a id='comment:5'></a>
No, actually, it's merely GAP producing a string that needs extra sanitation (in Python3).
Specifically, if I do the following

```
--- a/src/sage/libs/gap/util.pyx
+++ b/src/sage/libs/gap/util.pyx
@@ -507,8 +507,8 @@ cdef object extract_libgap_errout():
     msg = CSTR_STRING(r)
     if msg != NULL:
         msg_py = char_to_str(msg)
-        msg_py = msg_py.replace('For debugging hints type ?Recovery from '
-                                'NoMethodFound\n', '').strip()
+        #msg_py = msg_py.replace('For debugging hints type ?Recovery from '
+        #                        'NoMethodFound\n', '').strip()
     else:
         # Shouldn't happen but just in case...
         msg_py = ""
```
then all the tests on this file pass.

So, somehow, Python3 cannot correctly do search/replace/strip here, while Python2 can.
Any idea what to do?



---

archive/issue_comments_512396.json:
```json
{
    "body": "Changing status from new to needs_info.",
    "created_at": "2019-01-02T10:28:58Z",
    "issue": "https://github.com/sagemath/sagetest/issues/26992",
    "type": "issue_comment",
    "url": "https://github.com/sagemath/sagetest/issues/26992#issuecomment-512396",
    "user": "https://github.com/dimpase"
}
```

Changing status from new to needs_info.



---

archive/issue_comments_512397.json:
```json
{
    "body": "Set assignee to @embray.",
    "created_at": "2019-01-02T13:35:16Z",
    "issue": "https://github.com/sagemath/sagetest/issues/26992",
    "type": "issue_comment",
    "url": "https://github.com/sagemath/sagetest/issues/26992#issuecomment-512397",
    "user": "https://github.com/embray"
}
```

Set assignee to @embray.



---

archive/issue_comments_512398.json:
```json
{
    "body": "Changing branch from \"\" to \"u/embray/ticket-26992\"",
    "created_at": "2019-01-02T13:50:43Z",
    "issue": "https://github.com/sagemath/sagetest/issues/26992",
    "type": "issue_comment",
    "url": "https://github.com/sagemath/sagetest/issues/26992#issuecomment-512398",
    "user": "https://github.com/embray"
}
```

Changing branch from "" to "u/embray/ticket-26992"



---

archive/issue_comments_512399.json:
```json
{
    "body": "<a id='comment:7'></a>\nThe main issue here (which I've encountered before in other contexts) is that in Python 3 a lot of the interpreter and core types and modules are much stricter about checking whether or not an exception is already pending before trying to go down various code paths (without this you can end up in strange situations where built-in methods get called even after an exception has been raised).\n\nIn this case, the code in the error handler which manipulates the exception message (using Python) could break if the error handler was entered recursively, so it had to be reorganized slightly to account for this possibility.\n\nI also added `with gil` to both the error handler callback and the gasman callback: Although this isn't strictly necessary at the moment (it seems we don't release the GIL when entering libgap code) this was my first suspicion, and it's a good thing to do anyways just in case.\n\n---\nNew commits:\n|                                                                                                                                          |                                                                                  |\n|------------------------------------------------------------------------------------------------------------------------------------------|----------------------------------------------------------------------------------|\n|[3a99baf](https://github.com/sagemath/sagetrac-mirror/commit/3a99bafacf54a25203bccb581fd7d8fd14ee34ee)|`rearrange this code so that PyErr_Fetch is called before extract_libgap_errout()`|\n|[e5454ed](https://github.com/sagemath/sagetrac-mirror/commit/e5454ed538e4e750918733e7bf8b7ce462d9d2ba)|`ensure the GIL is held when entering these callback functions`|\n|[cbd1228](https://github.com/sagemath/sagetrac-mirror/commit/cbd12284c4403c52b01f2befae9436101ba6b2b4)|`trivial python3 test fix`|",
    "created_at": "2019-01-02T13:50:43Z",
    "issue": "https://github.com/sagemath/sagetest/issues/26992",
    "type": "issue_comment",
    "url": "https://github.com/sagemath/sagetest/issues/26992#issuecomment-512399",
    "user": "https://github.com/embray"
}
```

<a id='comment:7'></a>
The main issue here (which I've encountered before in other contexts) is that in Python 3 a lot of the interpreter and core types and modules are much stricter about checking whether or not an exception is already pending before trying to go down various code paths (without this you can end up in strange situations where built-in methods get called even after an exception has been raised).

In this case, the code in the error handler which manipulates the exception message (using Python) could break if the error handler was entered recursively, so it had to be reorganized slightly to account for this possibility.

I also added `with gil` to both the error handler callback and the gasman callback: Although this isn't strictly necessary at the moment (it seems we don't release the GIL when entering libgap code) this was my first suspicion, and it's a good thing to do anyways just in case.

---
New commits:
|                                                                                                                                          |                                                                                  |
|------------------------------------------------------------------------------------------------------------------------------------------|----------------------------------------------------------------------------------|
|[3a99baf](https://github.com/sagemath/sagetrac-mirror/commit/3a99bafacf54a25203bccb581fd7d8fd14ee34ee)|`rearrange this code so that PyErr_Fetch is called before extract_libgap_errout()`|
|[e5454ed](https://github.com/sagemath/sagetrac-mirror/commit/e5454ed538e4e750918733e7bf8b7ce462d9d2ba)|`ensure the GIL is held when entering these callback functions`|
|[cbd1228](https://github.com/sagemath/sagetrac-mirror/commit/cbd12284c4403c52b01f2befae9436101ba6b2b4)|`trivial python3 test fix`|



---

archive/issue_comments_512400.json:
```json
{
    "body": "Changing status from needs_info to needs_review.",
    "created_at": "2019-01-02T13:50:43Z",
    "issue": "https://github.com/sagemath/sagetest/issues/26992",
    "type": "issue_comment",
    "url": "https://github.com/sagemath/sagetest/issues/26992#issuecomment-512400",
    "user": "https://github.com/embray"
}
```

Changing status from needs_info to needs_review.



---

archive/issue_comments_512401.json:
```json
{
    "body": "Changing author from \"\" to \"Erik Bray\"",
    "created_at": "2019-01-02T13:50:43Z",
    "issue": "https://github.com/sagemath/sagetest/issues/26992",
    "type": "issue_comment",
    "url": "https://github.com/sagemath/sagetest/issues/26992#issuecomment-512401",
    "user": "https://github.com/embray"
}
```

Changing author from "" to "Erik Bray"



---

archive/issue_comments_512402.json:
```json
{
    "body": "Changing commit from \"\" to \"cbd12284c4403c52b01f2befae9436101ba6b2b4\"",
    "created_at": "2019-01-02T13:50:43Z",
    "issue": "https://github.com/sagemath/sagetest/issues/26992",
    "type": "issue_comment",
    "url": "https://github.com/sagemath/sagetest/issues/26992#issuecomment-512402",
    "user": "https://github.com/embray"
}
```

Changing commit from "" to "cbd12284c4403c52b01f2befae9436101ba6b2b4"



---

archive/issue_comments_512403.json:
```json
{
    "body": "<a id='comment:8'></a>\nlooks good to me - on py3 docbuilding (that was the place I saw this bug 1st) still breaks somewhere later, but this (a problem with `facade-sets` label) is another story for another ticket.",
    "created_at": "2019-01-03T15:11:32Z",
    "issue": "https://github.com/sagemath/sagetest/issues/26992",
    "type": "issue_comment",
    "url": "https://github.com/sagemath/sagetest/issues/26992#issuecomment-512403",
    "user": "https://github.com/dimpase"
}
```

<a id='comment:8'></a>
looks good to me - on py3 docbuilding (that was the place I saw this bug 1st) still breaks somewhere later, but this (a problem with `facade-sets` label) is another story for another ticket.



---

archive/issue_comments_512404.json:
```json
{
    "body": "Changing reviewer from \"\" to \"Dima Pasechnik\"",
    "created_at": "2019-01-03T15:11:32Z",
    "issue": "https://github.com/sagemath/sagetest/issues/26992",
    "type": "issue_comment",
    "url": "https://github.com/sagemath/sagetest/issues/26992#issuecomment-512404",
    "user": "https://github.com/dimpase"
}
```

Changing reviewer from "" to "Dima Pasechnik"



---

archive/issue_comments_512405.json:
```json
{
    "body": "Changing status from needs_review to positive_review.",
    "created_at": "2019-01-03T15:11:32Z",
    "issue": "https://github.com/sagemath/sagetest/issues/26992",
    "type": "issue_comment",
    "url": "https://github.com/sagemath/sagetest/issues/26992#issuecomment-512405",
    "user": "https://github.com/dimpase"
}
```

Changing status from needs_review to positive_review.



---

archive/issue_events_083863.json:
```json
{
    "actor": "https://github.com/embray",
    "created_at": "2019-01-15T18:16:10Z",
    "event": "milestoned",
    "issue": "https://github.com/sagemath/sagetest/issues/26992",
    "milestone": "sage-8.7",
    "type": "issue_event",
    "url": "https://github.com/sagemath/sagetest/issues/26992#event-83863"
}
```



---

archive/issue_comments_512406.json:
```json
{
    "body": "<a id='comment:9'></a>\nRetarging tickets optimistically to the next milestone.  If you are responsible for this ticket (either its reporter or owner) and don't believe you are likely to complete this ticket before the next release (8.7) please retarget this ticket's milestone to sage-pending or sage-wishlist.",
    "created_at": "2019-01-15T18:16:10Z",
    "issue": "https://github.com/sagemath/sagetest/issues/26992",
    "type": "issue_comment",
    "url": "https://github.com/sagemath/sagetest/issues/26992#issuecomment-512406",
    "user": "https://github.com/embray"
}
```

<a id='comment:9'></a>
Retarging tickets optimistically to the next milestone.  If you are responsible for this ticket (either its reporter or owner) and don't believe you are likely to complete this ticket before the next release (8.7) please retarget this ticket's milestone to sage-pending or sage-wishlist.



---

archive/issue_comments_512407.json:
```json
{
    "body": "Changing status from positive_review to needs_work.",
    "created_at": "2019-01-16T20:13:07Z",
    "issue": "https://github.com/sagemath/sagetest/issues/26992",
    "type": "issue_comment",
    "url": "https://github.com/sagemath/sagetest/issues/26992#issuecomment-512407",
    "user": "https://github.com/vbraun"
}
```

Changing status from positive_review to needs_work.



---

archive/issue_comments_512408.json:
```json
{
    "body": "<a id='comment:10'></a>\nMerge conflict",
    "created_at": "2019-01-16T20:13:07Z",
    "issue": "https://github.com/sagemath/sagetest/issues/26992",
    "type": "issue_comment",
    "url": "https://github.com/sagemath/sagetest/issues/26992#issuecomment-512408",
    "user": "https://github.com/vbraun"
}
```

<a id='comment:10'></a>
Merge conflict



---

archive/issue_comments_512409.json:
```json
{
    "body": "<a id='comment:11'></a>\nA mystery merge conflict.",
    "created_at": "2019-01-18T10:19:42Z",
    "issue": "https://github.com/sagemath/sagetest/issues/26992",
    "type": "issue_comment",
    "url": "https://github.com/sagemath/sagetest/issues/26992#issuecomment-512409",
    "user": "https://github.com/embray"
}
```

<a id='comment:11'></a>
A mystery merge conflict.



---

archive/issue_comments_512410.json:
```json
{
    "body": "<a id='comment:12'></a>\nWell, the pull request here is stalled..\n\nhttps://github.com/sagemath/git-trac-command/pull/30",
    "created_at": "2019-01-18T10:22:57Z",
    "issue": "https://github.com/sagemath/sagetest/issues/26992",
    "type": "issue_comment",
    "url": "https://github.com/sagemath/sagetest/issues/26992#issuecomment-512410",
    "user": "https://github.com/fchapoton"
}
```

<a id='comment:12'></a>
Well, the pull request here is stalled..

https://github.com/sagemath/git-trac-command/pull/30



---

archive/issue_comments_512411.json:
```json
{
    "body": "Changing branch from \"u/embray/ticket-26992\" to \"public/ticket/26992\"",
    "created_at": "2019-01-28T10:44:18Z",
    "issue": "https://github.com/sagemath/sagetest/issues/26992",
    "type": "issue_comment",
    "url": "https://github.com/sagemath/sagetest/issues/26992#issuecomment-512411",
    "user": "https://github.com/fchapoton"
}
```

Changing branch from "u/embray/ticket-26992" to "public/ticket/26992"



---

archive/issue_comments_512412.json:
```json
{
    "body": "Changing status from needs_work to positive_review.",
    "created_at": "2019-01-28T10:44:18Z",
    "issue": "https://github.com/sagemath/sagetest/issues/26992",
    "type": "issue_comment",
    "url": "https://github.com/sagemath/sagetest/issues/26992#issuecomment-512412",
    "user": "https://github.com/fchapoton"
}
```

Changing status from needs_work to positive_review.



---

archive/issue_comments_512413.json:
```json
{
    "body": "<a id='comment:13'></a>\ntrivial conflict fixed\n\n---\nNew commits:\n|                                                                                                                                          |                                                |\n|------------------------------------------------------------------------------------------------------------------------------------------|------------------------------------------------|\n|[369fade](https://github.com/sagemath/sagetrac-mirror/commit/369fade0a5c2ce0f5a6452d5e07065fd038bf07f)|`Merge branch 'u/embray/ticket-26992' in 8.7.b1`|",
    "created_at": "2019-01-28T10:44:18Z",
    "issue": "https://github.com/sagemath/sagetest/issues/26992",
    "type": "issue_comment",
    "url": "https://github.com/sagemath/sagetest/issues/26992#issuecomment-512413",
    "user": "https://github.com/fchapoton"
}
```

<a id='comment:13'></a>
trivial conflict fixed

---
New commits:
|                                                                                                                                          |                                                |
|------------------------------------------------------------------------------------------------------------------------------------------|------------------------------------------------|
|[369fade](https://github.com/sagemath/sagetrac-mirror/commit/369fade0a5c2ce0f5a6452d5e07065fd038bf07f)|`Merge branch 'u/embray/ticket-26992' in 8.7.b1`|



---

archive/issue_comments_512414.json:
```json
{
    "body": "Changing commit from \"cbd12284c4403c52b01f2befae9436101ba6b2b4\" to \"369fade0a5c2ce0f5a6452d5e07065fd038bf07f\"",
    "created_at": "2019-01-28T10:44:18Z",
    "issue": "https://github.com/sagemath/sagetest/issues/26992",
    "type": "issue_comment",
    "url": "https://github.com/sagemath/sagetest/issues/26992#issuecomment-512414",
    "user": "https://github.com/fchapoton"
}
```

Changing commit from "cbd12284c4403c52b01f2befae9436101ba6b2b4" to "369fade0a5c2ce0f5a6452d5e07065fd038bf07f"



---

archive/issue_comments_512415.json:
```json
{
    "body": "<a id='comment:14'></a>\nFollow-up ticket: #27155",
    "created_at": "2019-01-28T10:56:42Z",
    "issue": "https://github.com/sagemath/sagetest/issues/26992",
    "type": "issue_comment",
    "url": "https://github.com/sagemath/sagetest/issues/26992#issuecomment-512415",
    "user": "https://github.com/jdemeyer"
}
```

<a id='comment:14'></a>
Follow-up ticket: #27155



---

archive/issue_comments_512416.json:
```json
{
    "body": "<a id='comment:15'></a>\nNote that this usage of `PyErr_Fetch()` is a memory leak: the objects which are returned by `PyErr_Fetch` should be deallocated explicitly (if you are dealing with `PyObject*` instead of `object`, Cython doesn't take care of refcounts). I'll fix that on #27155.",
    "created_at": "2019-01-28T11:02:36Z",
    "issue": "https://github.com/sagemath/sagetest/issues/26992",
    "type": "issue_comment",
    "url": "https://github.com/sagemath/sagetest/issues/26992#issuecomment-512416",
    "user": "https://github.com/jdemeyer"
}
```

<a id='comment:15'></a>
Note that this usage of `PyErr_Fetch()` is a memory leak: the objects which are returned by `PyErr_Fetch` should be deallocated explicitly (if you are dealing with `PyObject*` instead of `object`, Cython doesn't take care of refcounts). I'll fix that on #27155.



---

archive/issue_comments_512417.json:
```json
{
    "body": "<a id='comment:16'></a>\nI'm getting a quite consistent error (with or without 27155)\n\n```\n**********************************************************************\nFile \"src/sage/groups/matrix_gps/coxeter_group.py\", line 421, in sage.groups.matrix_gps.coxeter_group.CoxeterMatrixGroup.is_finite\nFailed example:\n    [l for l in range(2, 9) if\n     CoxeterGroup([[1,3,2,2,2], [3,1,3,3,2], [2,3,1,2,2],\n                   [2,3,2,1,l], [2,2,2,l,1]]).is_finite()]\nException raised:\n    Traceback (most recent call last):\n      File \"/var/lib/buildbot/slave/sage_git/build/local/lib/python2.7/site-packages/sage/doctest/forker.py\", line 671, in _run\n        self.compile_and_execute(example, compiler, test.globs)\n      File \"/var/lib/buildbot/slave/sage_git/build/local/lib/python2.7/site-packages/sage/doctest/forker.py\", line 1095, in compile_and_execute\n        exec(compiled, globs)\n      File \"<doctest sage.groups.matrix_gps.coxeter_group.CoxeterMatrixGroup.is_finite[2]>\", line 3, in <module>\n        [Integer(2),Integer(3),Integer(2),Integer(1),l], [Integer(2),Integer(2),Integer(2),l,Integer(1)]]).is_finite()]\n      File \"sage/misc/lazy_import.pyx\", line 354, in sage.misc.lazy_import.LazyImport.__call__ (build/cythonized/sage/misc/lazy_import.c:3683)\n        return self.get_object()(*args, **kwds)\n      File \"/var/lib/buildbot/slave/sage_git/build/local/lib/python2.7/site-packages/sage/combinat/root_system/coxeter_group.py\", line 132, in CoxeterGroup\n        return CoxeterMatrixGroup(data, base_ring, index_set)\n      File \"sage/misc/classcall_metaclass.pyx\", line 330, in sage.misc.classcall_metaclass.ClasscallMetaclass.__call__ (build/cythonized/sage/misc/classcall_metaclass.c:1700)\n        return cls.classcall(cls, *args, **kwds)\n      File \"/var/lib/buildbot/slave/sage_git/build/local/lib/python2.7/site-packages/sage/groups/matrix_gps/coxeter_group.py\", line 233, in __classcall_private__\n        data, base_ring, data.index_set())\n      File \"sage/misc/cachefunc.pyx\", line 1005, in sage.misc.cachefunc.CachedFunction.__call__ (build/cythonized/sage/misc/cachefunc.c:6067)\n        w = self.f(*args, **kwds)\n      File \"/var/lib/buildbot/slave/sage_git/build/local/lib/python2.7/site-packages/sage/structure/unique_representation.py\", line 1027, in __classcall__\n        instance = typecall(cls, *args, **options)\n      File \"sage/misc/classcall_metaclass.pyx\", line 497, in sage.misc.classcall_metaclass.typecall (build/cythonized/sage/misc/classcall_metaclass.c:2150)\n        return (<PyTypeObject*>type).tp_call(cls, args, kwds)\n      File \"/var/lib/buildbot/slave/sage_git/build/local/lib/python2.7/site-packages/sage/groups/matrix_gps/coxeter_group.py\", line 303, in __init__\n        for i in range(n)]\n      File \"/var/lib/buildbot/slave/sage_git/build/local/lib/python2.7/site-packages/sage/groups/matrix_gps/coxeter_group.py\", line 284, in val\n        return E(2 * x) + ~E(2 * x)\n      File \"/var/lib/buildbot/slave/sage_git/build/local/lib/python2.7/site-packages/sage/rings/universal_cyclotomic_field.py\", line 1258, in gen\n        return self.element_class(self, libgap.E(n)**k)\n      File \"sage/libs/gap/element.pyx\", line 1062, in sage.libs.gap.element.GapElement.__pow__ (build/cythonized/sage/libs/gap/element.c:10893)\n        sig_on()\n    SystemError: calling remove_from_pari_stack() inside sig_on()\n**********************************************************************\n1 item had failures:\n   1 of   6 in sage.groups.matrix_gps.coxeter_group.CoxeterMatrixGroup.is_finite\n    [136 tests, 1 failure, 4.76 s]\n----------------------------------------------------------------------\nsage -t --long src/sage/groups/matrix_gps/coxeter_group.py  # 1 doctest failed\n----------------------------------------------------------------------\n```",
    "created_at": "2019-02-02T15:02:21Z",
    "issue": "https://github.com/sagemath/sagetest/issues/26992",
    "type": "issue_comment",
    "url": "https://github.com/sagemath/sagetest/issues/26992#issuecomment-512417",
    "user": "https://github.com/vbraun"
}
```

<a id='comment:16'></a>
I'm getting a quite consistent error (with or without 27155)

```
**********************************************************************
File "src/sage/groups/matrix_gps/coxeter_group.py", line 421, in sage.groups.matrix_gps.coxeter_group.CoxeterMatrixGroup.is_finite
Failed example:
    [l for l in range(2, 9) if
     CoxeterGroup([[1,3,2,2,2], [3,1,3,3,2], [2,3,1,2,2],
                   [2,3,2,1,l], [2,2,2,l,1]]).is_finite()]
Exception raised:
    Traceback (most recent call last):
      File "/var/lib/buildbot/slave/sage_git/build/local/lib/python2.7/site-packages/sage/doctest/forker.py", line 671, in _run
        self.compile_and_execute(example, compiler, test.globs)
      File "/var/lib/buildbot/slave/sage_git/build/local/lib/python2.7/site-packages/sage/doctest/forker.py", line 1095, in compile_and_execute
        exec(compiled, globs)
      File "<doctest sage.groups.matrix_gps.coxeter_group.CoxeterMatrixGroup.is_finite[2]>", line 3, in <module>
        [Integer(2),Integer(3),Integer(2),Integer(1),l], [Integer(2),Integer(2),Integer(2),l,Integer(1)]]).is_finite()]
      File "sage/misc/lazy_import.pyx", line 354, in sage.misc.lazy_import.LazyImport.__call__ (build/cythonized/sage/misc/lazy_import.c:3683)
        return self.get_object()(*args, **kwds)
      File "/var/lib/buildbot/slave/sage_git/build/local/lib/python2.7/site-packages/sage/combinat/root_system/coxeter_group.py", line 132, in CoxeterGroup
        return CoxeterMatrixGroup(data, base_ring, index_set)
      File "sage/misc/classcall_metaclass.pyx", line 330, in sage.misc.classcall_metaclass.ClasscallMetaclass.__call__ (build/cythonized/sage/misc/classcall_metaclass.c:1700)
        return cls.classcall(cls, *args, **kwds)
      File "/var/lib/buildbot/slave/sage_git/build/local/lib/python2.7/site-packages/sage/groups/matrix_gps/coxeter_group.py", line 233, in __classcall_private__
        data, base_ring, data.index_set())
      File "sage/misc/cachefunc.pyx", line 1005, in sage.misc.cachefunc.CachedFunction.__call__ (build/cythonized/sage/misc/cachefunc.c:6067)
        w = self.f(*args, **kwds)
      File "/var/lib/buildbot/slave/sage_git/build/local/lib/python2.7/site-packages/sage/structure/unique_representation.py", line 1027, in __classcall__
        instance = typecall(cls, *args, **options)
      File "sage/misc/classcall_metaclass.pyx", line 497, in sage.misc.classcall_metaclass.typecall (build/cythonized/sage/misc/classcall_metaclass.c:2150)
        return (<PyTypeObject*>type).tp_call(cls, args, kwds)
      File "/var/lib/buildbot/slave/sage_git/build/local/lib/python2.7/site-packages/sage/groups/matrix_gps/coxeter_group.py", line 303, in __init__
        for i in range(n)]
      File "/var/lib/buildbot/slave/sage_git/build/local/lib/python2.7/site-packages/sage/groups/matrix_gps/coxeter_group.py", line 284, in val
        return E(2 * x) + ~E(2 * x)
      File "/var/lib/buildbot/slave/sage_git/build/local/lib/python2.7/site-packages/sage/rings/universal_cyclotomic_field.py", line 1258, in gen
        return self.element_class(self, libgap.E(n)**k)
      File "sage/libs/gap/element.pyx", line 1062, in sage.libs.gap.element.GapElement.__pow__ (build/cythonized/sage/libs/gap/element.c:10893)
        sig_on()
    SystemError: calling remove_from_pari_stack() inside sig_on()
**********************************************************************
1 item had failures:
   1 of   6 in sage.groups.matrix_gps.coxeter_group.CoxeterMatrixGroup.is_finite
    [136 tests, 1 failure, 4.76 s]
----------------------------------------------------------------------
sage -t --long src/sage/groups/matrix_gps/coxeter_group.py  # 1 doctest failed
----------------------------------------------------------------------
```



---

archive/issue_comments_512418.json:
```json
{
    "body": "Changing status from positive_review to needs_work.",
    "created_at": "2019-02-02T15:02:21Z",
    "issue": "https://github.com/sagemath/sagetest/issues/26992",
    "type": "issue_comment",
    "url": "https://github.com/sagemath/sagetest/issues/26992#issuecomment-512418",
    "user": "https://github.com/vbraun"
}
```

Changing status from positive_review to needs_work.



---

archive/issue_comments_512419.json:
```json
{
    "body": "<a id='comment:17'></a>\nYes, this #27140. I was hoping to fix that error on top of #26992 and #27155.",
    "created_at": "2019-02-04T11:31:32Z",
    "issue": "https://github.com/sagemath/sagetest/issues/26992",
    "type": "issue_comment",
    "url": "https://github.com/sagemath/sagetest/issues/26992#issuecomment-512419",
    "user": "https://github.com/jdemeyer"
}
```

<a id='comment:17'></a>
Yes, this #27140. I was hoping to fix that error on top of #26992 and #27155.



---

archive/issue_events_083864.json:
```json
{
    "actor": "https://github.com/jdemeyer",
    "created_at": "2019-02-04T11:31:32Z",
    "event": "demilestoned",
    "issue": "https://github.com/sagemath/sagetest/issues/26992",
    "milestone": "sage-8.7",
    "type": "issue_event",
    "url": "https://github.com/sagemath/sagetest/issues/26992#event-83864"
}
```



---

archive/issue_events_083865.json:
```json
{
    "actor": "https://github.com/jdemeyer",
    "created_at": "2019-02-04T11:31:32Z",
    "event": "milestoned",
    "issue": "https://github.com/sagemath/sagetest/issues/26992",
    "milestone": "sage-pending",
    "type": "issue_event",
    "url": "https://github.com/sagemath/sagetest/issues/26992#event-83865"
}
```



---

archive/issue_comments_512420.json:
```json
{
    "body": "Changing status from needs_work to positive_review.",
    "created_at": "2019-02-04T11:31:32Z",
    "issue": "https://github.com/sagemath/sagetest/issues/26992",
    "type": "issue_comment",
    "url": "https://github.com/sagemath/sagetest/issues/26992#issuecomment-512420",
    "user": "https://github.com/jdemeyer"
}
```

Changing status from needs_work to positive_review.



---

archive/issue_comments_512421.json:
```json
{
    "body": "<a id='comment:18'></a>\nTo the release manager: tickets #26992, #27155 and #27140 should be merged together to avoid test failures.",
    "created_at": "2019-02-05T15:18:29Z",
    "issue": "https://github.com/sagemath/sagetest/issues/26992",
    "type": "issue_comment",
    "url": "https://github.com/sagemath/sagetest/issues/26992#issuecomment-512421",
    "user": "https://github.com/jdemeyer"
}
```

<a id='comment:18'></a>
To the release manager: tickets #26992, #27155 and #27140 should be merged together to avoid test failures.



---

archive/issue_events_083866.json:
```json
{
    "actor": "https://github.com/jdemeyer",
    "created_at": "2019-02-05T15:18:29Z",
    "event": "demilestoned",
    "issue": "https://github.com/sagemath/sagetest/issues/26992",
    "milestone": "sage-pending",
    "type": "issue_event",
    "url": "https://github.com/sagemath/sagetest/issues/26992#event-83866"
}
```



---

archive/issue_events_083867.json:
```json
{
    "actor": "https://github.com/jdemeyer",
    "created_at": "2019-02-05T15:18:29Z",
    "event": "milestoned",
    "issue": "https://github.com/sagemath/sagetest/issues/26992",
    "milestone": "sage-8.7",
    "type": "issue_event",
    "url": "https://github.com/sagemath/sagetest/issues/26992#event-83867"
}
```



---

archive/issue_comments_512422.json:
```json
{
    "body": "Resolution: fixed",
    "created_at": "2019-02-06T10:39:19Z",
    "issue": "https://github.com/sagemath/sagetest/issues/26992",
    "type": "issue_comment",
    "url": "https://github.com/sagemath/sagetest/issues/26992#issuecomment-512422",
    "user": "https://github.com/vbraun"
}
```

Resolution: fixed



---

archive/issue_events_083868.json:
```json
{
    "actor": "https://github.com/vbraun",
    "created_at": "2019-02-06T10:39:19Z",
    "event": "closed",
    "issue": "https://github.com/sagemath/sagetest/issues/26992",
    "type": "issue_event",
    "url": "https://github.com/sagemath/sagetest/issues/26992#event-83868"
}
```



---

archive/issue_comments_512423.json:
```json
{
    "body": "Changing branch from \"public/ticket/26992\" to \"369fade0a5c2ce0f5a6452d5e07065fd038bf07f\"",
    "created_at": "2019-02-06T10:39:19Z",
    "issue": "https://github.com/sagemath/sagetest/issues/26992",
    "type": "issue_comment",
    "url": "https://github.com/sagemath/sagetest/issues/26992#issuecomment-512423",
    "user": "https://github.com/vbraun"
}
```

Changing branch from "public/ticket/26992" to "369fade0a5c2ce0f5a6452d5e07065fd038bf07f"
